---
title: Java异常处理
date: 2022-07-13 16:28:42
permalink: /pages/8bbc8a/
categories:
  - Java
  - Java基础
  - 基础知识
tags:
  - Java
author: 
  name: Marvel
  link: https://github.com/zouquchen
---
# Java异常处理

## 异常类的层次结构

<img src="https://raw.githubusercontent.com/zouquchen/Images/main/imgs/Exception-relationship.png" alt="image-20220718142200371" style="zoom:67%;" />

在 Java 中，所有的异常都有一个共同的祖先 `java.lang` 包中的 `Throwable` 类。`Throwable` 类有两个重要的子类：

- **异常 `Exception`** ：程序本身可以处理的异常，可以通过 `catch` 来进行捕获
  - 检查性异常 `Checked Exception` ：必须处理
  - 运行时异常 `Runtime Exception` ：可以不处理
- **错误 `Error`** ：属于程序无法处理的错误。

### 检查性异常

Java 代码在编译过程中，如果受检查异常没有被 `catch`/`throw` 处理的话，就没办法通过编译 。

<img src="https://raw.githubusercontent.com/zouquchen/Images/main/imgs/Exception-Checked-Exception%20.png" alt="Checked Exception" style="zoom:67%;" />

此时运行程序

```Output
java: 未报告的异常错误java.lang.InterruptedException; 必须对其进行捕获或声明以便抛出
```

### 运行时异常

Java 代码在编译过程中 ，我们即使不处理运行时异常也可以正常通过编译。

`RuntimeException` 及其子类都统称为运行时异常，例如：

- `NullPointerException`：空指针异常

- `NumberFormatException`：字符串转换为数字异常

- `ArrayIndexOutOfBoundsException`：数组越界

- `ClassCastException`：类型转换错误

- `ArithmeticException`：算术错误
- `ConcurrentModificationException`：并发修改异常

### 错误

错误不是异常，而是脱离程序员控制的问题，它们在编译期间检查不到的，当错误发生程序会立刻停止。

> 「错误」不是「异常」，但是我们经常把「错误」称为「异常」，比如OOM异常，其实指的是OOM错误。

常见错误有：

- `java.lang.OutOfMemoryError`：内存溢出错误
- `java.lang.StackOverflowError`：栈溢出错误

## Throwable 类常用方法

- `String getMessage()`: 返回异常发生时的简要描述
- `String toString()`: 返回异常发生时的详细信息
- `String getLocalizedMessage()`: 返回异常对象的本地化信息。使用 `Throwable` 的子类覆盖这个方法，可以生成本地化信息。如果子类没有覆盖该方法，则该方法返回的信息与 `getMessage()`返回的结果相同
- `void printStackTrace()`: 在控制台上打印 `Throwable` 对象封装的异常信息

## 异常捕获 try-catch-finally

- **`try`块：** 用于捕获异常。其后可接零个或多个 `catch` 块，如果没有 `catch` 块，则必须跟一个 `finally` 块。
- **`catch`块：** 用于处理 try 捕获到的异常，可以有多个 `catch` 块，每个块用于捕获不同的异常。
- **`finally` 块：** 无论是否捕获或处理异常，`finally` 块里的语句都会被执行。当在 `try` 块或 `catch` 块中遇到 `return` 语句时，`finally` 语句块将在方法返回之前被执行。

### try-catch-finally执行顺序

示例：

```Java
try {
    System.out.println("Try to do something");
    throw new RuntimeException("RuntimeException");
} catch (Exception e) {
    System.out.println("Catch Exception -> " + e.getMessage());
} finally {
    System.out.println("Finally");
}
```

输出：

```Output
Try to do something
Catch Exception -> RuntimeException
Finally
```

### return与finally

1. 当在 `try` 块或 `catch` 块中遇到 `return` 语句时，`finally` 语句块将在方法返回之前被执行。
2. 不要在 `finally` 语句块中使用 `return`！当 `try` 语句和 `finally` 语句中都有 `return` 语句时，`try` 语句块中的 `return` 语句会被忽略。这是因为 `try` 语句中的 `return` 返回值会先被暂存在一个本地变量中，当执行到 `finally` 语句中的 `return` 之后，这个本地变量的值就变为了 `finally` 语句中的 `return` 返回值。
3. 在特殊情况下 `finally` 中的代码不会被执行，就比如说 `finally` 之前虚拟机被终止运行的话，`finally` 中的代码就不会被执行。

// TODO：从字节码理解执行顺序



## 语法糖 try-with-resources

JDK7 之后，Java 新增的 `try-with-resource` 语法糖来打开资源，并且可以在语句执行完毕后确保每个资源都被自动关闭 。

```Java
try (resource declaration) {
  // 使用的资源
} catch (ExceptionType e1) {
  // 异常块
}
```

示例：

```Java
import java.io.*;

public class RunoobTest {

    public static void main(String[] args) {
    String line;
        try(BufferedReader br = new BufferedReader(new FileReader("test.txt"))) {
            while ((line = br.readLine()) != null) {
                System.out.println("Line =>"+line);
            }
        } catch (IOException e) {
            System.out.println("IOException in try block =>" + e.getMessage());
        }
    }
}
```



## 关键字 throws/throw

⭐ **throws**：用来声明一个方法可能产生的所有异常，不做任何处理而是将异常往上传，谁调用我我就抛给谁。

```Java
public class className
{
  public void deposit(double amount) throws RemoteException
  {
    // Method implementation
    throw new RemoteException();
  }
  //Remainder of class definition
}
```



⭐ **throw**：用来抛出一个具体的异常类型

```Java
public class Test {
    public static void main(String[] args) {
        User user1 = new User("admin", "123");
        User user2 = null;
        login(user1);
        login(user2);
    }

    public static void login(User user) {
        if (user == null) {
            // 这里可以通过继承RuntimeException来自定义异常
            throw new RuntimeException("传入用户参数异常");
        }
        System.out.println("登录成功！");
    }
}
class User {
    private String username;
    private String password;

    public User(String username, String password) {
        this.username = username;
        this.password = password;
    }

    public String getUsername() {
        return username;
    }

    public String getPassword() {
        return password;
    }
}
```

控制台输出

```Output{2}
登录成功！
Exception in thread "main" java.lang.RuntimeException: 传入用户参数异常
	at test.Test.login(Test.java:25)
	at test.Test.main(Test.java:20)
```

`catch` 块捕获异常，自定义抛出异常。